<?xml version="1.0"?>
<robot xmlns:xacro="http://www.ros.org/wiki/xacro" name="thorvald_arm">

    <!-- Import the materials -->
    <xacro:include filename="macros.xacro"/>

    <xacro:macro name="thorvald_arm" params="name parent xyz rpy">
        <!-- Base Link -->
        <link name="${name}_base_link"/>
        <joint name="${name}_base_joint" type="prismatic">
            <parent link="${parent}"/>
            <child link="${name}_base_link"/>
            <origin xyz="${xyz}" rpy="${rpy}"/>
            <axis xyz="0 0 1"/>
            <limit effort="10" lower="-0.5" upper="0" velocity="0.5"/>
        </joint>

        <!-- Joint 1 -->
        <xacro:stl name="${name}_arm1_link" filename="Arm_joint_1.stl"/>
        <joint name="${name}_joint_1" type="revolute">
            <parent link="${name}_base_link"/>
            <child link="${name}_arm1_link"/>
            <origin xyz="0 0 0" rpy="0 0 0"/>
            <axis xyz="0 0 1"/>
            <limit effort="10.0" velocity="1.0" lower="-1.57" upper="1.57"/>
        </joint>

        <!-- Joint 2 -->
        <xacro:stl name="${name}_arm2_link" filename="Arm_joint_2.stl"/>
        <joint name="${name}_joint_2" type="revolute">
            <parent link="${name}_arm1_link"/>
            <child link="${name}_arm2_link"/>
            <origin xyz="0 0.2 0" rpy="0 0 0"/>
            <axis xyz="0 0 1"/>
            <limit effort="10.0" velocity="1.0" lower="-2.5" upper="2.5"/>
        </joint>

        <!-- Joint 3 -->
        <xacro:stl name="${name}_base_offset_link" filename="End effector.stl"/>
        <joint name="${name}_joint_3" type="revolute">
            <parent link="${name}_arm2_link"/>
            <child link="${name}_base_offset_link"/>
            <origin xyz="0 0.16 0.025" rpy="1.57 0 0"/>
            <axis xyz="0 1 0"/>
            <limit effort="10.0" velocity="1.0" lower="0" upper="0"/>
        </joint>
        
        <!-- Joint 4 -->
        <xacro:stl name="${name}_end1_link" filename="End_joint_1.stl"/>
        <joint name="${name}_joint_4" type="revolute">
            <parent link="${name}_base_offset_link"/>
            <child link="${name}_end1_link"/>
            <origin xyz="0 0.223 -0.02" rpy="0 1.57 0"/>
            <axis xyz="0 1 0"/>
            <limit effort="10.0" velocity="1.0" lower="-1.57" upper="1.57"/>
        </joint>

        <!-- Joint 5 -->
        <xacro:stl name="${name}_end2_link" filename="End_joint_2.stl"/>
        <joint name="${name}_joint_5" type="revolute">
            <parent link="${name}_end1_link"/>
            <child link="${name}_end2_link"/>
            <origin xyz="0.05 -0.015 0.018" rpy="1.57 0 0"/>
            <axis xyz="0 1 0"/>
            <limit effort="10.0" velocity="1.0" lower="-2" upper="2"/>
        </joint>

        <link name="${name}_end_effector_link"/>
        <joint name="${name}_joint_6" type="fixed">
            <parent link="${name}_end2_link"/>
            <child link="${name}_end_effector_link"/>
            <origin xyz="0.04 -0.016 0" rpy="0 0 0"/>
        </joint>

    </xacro:macro>

</robot>
